<?xml version="0.0" ?>
<robot name="">
	<link name="link1_1">
		<inertial>
			<origin rpy="0.00000 -0.00000 0.00000" xyz="0.00000 0.00000 0.00000"/>
			<mass value="0.00000"/>
			<inertia ixx="0.00000" ixy="0" ixz="0" iyy="0.00000" iyz="0" izz="0.00000"/>
		</inertial>
	</link>
	<link name="link1_2">
		<inertial>
			<origin rpy="0.00000 -0.00000 0.00000" xyz="0.00000 0.00000 0.00000"/>
			<mass value="0.00000"/>
			<inertia ixx="0.00000" ixy="0" ixz="0" iyy="0.00000" iyz="0" izz="0.00000"/>
		</inertial>
	</link>
	<link name="shoulder_pan_link">
		<inertial>
			<origin rpy="0.00000 -0.00000 0.00000" xyz="0.00000 0.00000 -0.10000"/>
			<mass value="24.31174"/>
			<inertia ixx="1.39468" ixy="0" ixz="0" iyy="1.39468" iyz="0" izz="0.19611"/>
		</inertial>
		<collision>
			<origin rpy="0.00000 -0.00000 0.00000" xyz="-0.06000 0.05000 0.20000"/>
			<geometry>
				<sphere radius="0.05000"/>
			</geometry>
		</collision>
		<collision>
			<origin rpy="0.00000 -0.00000 0.00000" xyz="0.06000 0.05000 0.20000"/>
			<geometry>
				<sphere radius="0.05000"/>
			</geometry>
		</collision>
		<collision>
			<origin rpy="0.00000 -0.00000 0.00000" xyz="-0.06000 0.09000 0.20000"/>
			<geometry>
				<sphere radius="0.03000"/>
			</geometry>
		</collision>
		<collision>
			<origin rpy="0.00000 -0.00000 0.00000" xyz="0.06000 0.09000 0.20000"/>
			<geometry>
				<sphere radius="0.03000"/>
			</geometry>
		</collision>
		<collision>
			<origin rpy="0.00000 -0.00000 0.00000" xyz="0.00000 0.00000 -0.10000"/>
			<geometry>
				<capsule length="0.60000" radius="0.10000"/>
			</geometry>
		</collision>
	</link>
	<link name="link1_4">
		<inertial>
			<origin rpy="0.00000 -0.00000 0.00000" xyz="0.00000 0.00000 0.00000"/>
			<mass value="0.00000"/>
			<inertia ixx="0.00000" ixy="0" ixz="0" iyy="0.00000" iyz="0" izz="0.00000"/>
		</inertial>
	</link>
	<link name="shoulder_lift_link">
		<inertial>
			<origin rpy="0.00000 -0.00000 0.00000" xyz="0.00000 0.00000 0.00000"/>
			<mass value="10.47198"/>
			<inertia ixx="0.17453" ixy="0" ixz="0" iyy="0.06981" iyz="0" izz="0.17453"/>
		</inertial>
		<collision>
			<origin rpy="-1.57080 0.00000 0.00000" xyz="0.00000 0.00000 0.00000"/>
			<geometry>
				<capsule length="0.20000" radius="0.10000"/>
			</geometry>
		</collision>
	</link>
	<link name="link1_6">
		<inertial>
			<origin rpy="0.00000 -0.00000 0.00000" xyz="0.00000 0.00000 0.00000"/>
			<mass value="0.00000"/>
			<inertia ixx="0.00000" ixy="0" ixz="0" iyy="0.00000" iyz="0" izz="0.00000"/>
		</inertial>
	</link>
	<link name="upper_arm_roll_link">
		<inertial>
			<origin rpy="0.00000 -0.00000 0.00000" xyz="0.00000 0.00000 0.00000"/>
			<mass value="0.28484"/>
			<inertia ixx="0.00008" ixy="0" ixz="0" iyy="0.00141" iyz="0" izz="0.00141"/>
		</inertial>
		<collision>
			<origin rpy="0.00000 1.57080 -0.00000" xyz="0.00000 0.00000 0.00000"/>
			<geometry>
				<capsule length="0.20000" radius="0.02000"/>
			</geometry>
		</collision>
	</link>
	<link name="upper_arm_link">
		<inertial>
			<origin rpy="0.00000 -0.00000 0.00000" xyz="0.20000 0.00000 0.00000"/>
			<mass value="5.42867"/>
			<inertia ixx="0.01303" ixy="0" ixz="0" iyy="0.12884" iyz="0" izz="0.12884"/>
		</inertial>
		<collision>
			<origin rpy="0.00000 1.57080 -0.00000" xyz="0.20000 0.00000 0.00000"/>
			<geometry>
				<capsule length="0.40000" radius="0.06000"/>
			</geometry>
		</collision>
	</link>
	<link name="link1_9">
		<inertial>
			<origin rpy="0.00000 -0.00000 0.00000" xyz="0.00000 0.00000 0.00000"/>
			<mass value="0.00000"/>
			<inertia ixx="0.00000" ixy="0" ixz="0" iyy="0.00000" iyz="0" izz="0.00000"/>
		</inertial>
	</link>
	<link name="elbow_flex_link">
		<inertial>
			<origin rpy="0.00000 -0.00000 0.00000" xyz="0.00000 0.00000 0.00000"/>
			<mass value="1.35717"/>
			<inertia ixx="0.00452" ixy="0" ixz="0" iyy="0.00326" iyz="0" izz="0.00452"/>
		</inertial>
		<collision>
			<origin rpy="-1.57080 0.00000 0.00000" xyz="0.00000 0.00000 0.00000"/>
			<geometry>
				<capsule length="0.04000" radius="0.06000"/>
			</geometry>
		</collision>
	</link>
	<link name="link1_11">
		<inertial>
			<origin rpy="0.00000 -0.00000 0.00000" xyz="0.00000 0.00000 0.00000"/>
			<mass value="0.00000"/>
			<inertia ixx="0.00000" ixy="0" ixz="0" iyy="0.00000" iyz="0" izz="0.00000"/>
		</inertial>
	</link>
	<link name="forearm_roll_link">
		<inertial>
			<origin rpy="0.00000 -0.00000 0.00000" xyz="0.00000 0.00000 0.00000"/>
			<mass value="0.28484"/>
			<inertia ixx="0.00008" ixy="0" ixz="0" iyy="0.00141" iyz="0" izz="0.00141"/>
		</inertial>
		<collision>
			<origin rpy="0.00000 1.57080 -0.00000" xyz="0.00000 0.00000 0.00000"/>
			<geometry>
				<capsule length="0.20000" radius="0.02000"/>
			</geometry>
		</collision>
	</link>
	<link name="forearm_link">
		<inertial>
			<origin rpy="0.00000 -0.00000 0.00000" xyz="0.14550 0.00000 0.00000"/>
			<mass value="2.80911"/>
			<inertia ixx="0.00468" ixy="0" ixz="0" iyy="0.03813" iyz="0" izz="0.03813"/>
		</inertial>
		<collision>
			<origin rpy="0.00000 1.57080 -0.00000" xyz="0.14550 0.00000 0.00000"/>
			<geometry>
				<capsule length="0.29100" radius="0.05000"/>
			</geometry>
		</collision>
	</link>
	<link name="link1_14">
		<inertial>
			<origin rpy="0.00000 -0.00000 0.00000" xyz="0.00000 0.00000 0.00000"/>
			<mass value="0.00000"/>
			<inertia ixx="0.00000" ixy="0" ixz="0" iyy="0.00000" iyz="0" izz="0.00000"/>
		</inertial>
	</link>
	<link name="wrist_flex_link">
		<inertial>
			<origin rpy="0.00000 -0.00000 0.00000" xyz="0.00000 0.00000 0.00000"/>
			<mass value="0.01676"/>
			<inertia ixx="0.00001" ixy="0" ixz="0" iyy="0.00000" iyz="0" izz="0.00001"/>
		</inertial>
		<collision>
			<origin rpy="-1.57080 0.00000 0.00000" xyz="0.00000 0.00000 0.00000"/>
			<geometry>
				<capsule length="0.04000" radius="0.01000"/>
			</geometry>
		</collision>
	</link>
	<link name="link1_16">
		<inertial>
			<origin rpy="0.00000 -0.00000 0.00000" xyz="0.00000 0.00000 0.00000"/>
			<mass value="0.00000"/>
			<inertia ixx="0.00000" ixy="0" ixz="0" iyy="0.00000" iyz="0" izz="0.00000"/>
		</inertial>
	</link>
	<link name="wrist_roll_link">
		<inertial>
			<origin rpy="0.00000 -0.00000 0.00000" xyz="0.05000 0.10000 0.00000"/>
			<mass value="0.60319"/>
			<inertia ixx="0.00298" ixy="0" ixz="0" iyy="0.00107" iyz="0" izz="0.00388"/>
		</inertial>
		<collision>
			<origin rpy="-1.57080 0.00000 0.00000" xyz="0.00000 0.00000 0.00000"/>
			<geometry>
				<capsule length="0.20000" radius="0.02000"/>
			</geometry>
		</collision>
		<collision>
			<origin rpy="0.00000 1.57080 -0.00000" xyz="0.05000 -0.10000 0.00000"/>
			<geometry>
				<capsule length="0.10000" radius="0.02000"/>
			</geometry>
		</collision>
		<collision>
			<origin rpy="0.00000 1.57080 -0.00000" xyz="0.05000 0.10000 0.00000"/>
			<geometry>
				<capsule length="0.10000" radius="0.02000"/>
			</geometry>
		</collision>
	</link>
	<link name="fingertip">
		<inertial>
			<origin rpy="0.00000 -0.00000 0.00000" xyz="0.00000 0.00000 0.00000"/>
			<mass value="0.00838"/>
			<inertia ixx="0.00003" ixy="0" ixz="0" iyy="0.00000" iyz="0" izz="0.00003"/>
		</inertial>
		<collision>
			<origin rpy="0.00000 -0.00000 0.00000" xyz="0.10000 -0.10000 0.00000"/>
			<geometry>
				<sphere radius="0.01000"/>
			</geometry>
		</collision>
		<collision>
			<origin rpy="0.00000 -0.00000 0.00000" xyz="0.10000 0.10000 0.00000"/>
			<geometry>
				<sphere radius="0.01000"/>
			</geometry>
		</collision>
	</link>
	<joint name="shoulder_pan_joint" type="continuous">
		<parent link="link1_1"/>
		<child link="link1_2"/>
		<dynamics damping="1.0" friction="0.0001"/>
		<origin rpy="0.00000 -0.00000 0.00000" xyz="0.00000 -0.60000 0.00000"/>
		<axis xyz="0.00000 0.00000 1.00000"/>
	</joint>
	<joint name="jointfix_9_2" type="fixed">
		<parent link="link1_2"/>
		<child link="shoulder_pan_link"/>
		<dynamics damping="1.0" friction="0.0001"/>
		<origin rpy="0.00000 -0.00000 0.00000" xyz="0.00000 0.00000 0.00000"/>
		<axis xyz="0.00000 0.00000 0.00000"/>
	</joint>
	<joint name="shoulder_lift_joint" type="continuous">
		<parent link="shoulder_pan_link"/>
		<child link="link1_4"/>
		<dynamics damping="1.0" friction="0.0001"/>
		<origin rpy="0.00000 -0.00000 0.00000" xyz="0.10000 0.00000 0.00000"/>
		<axis xyz="0.00000 1.00000 0.00000"/>
	</joint>
	<joint name="jointfix_8_4" type="fixed">
		<parent link="link1_4"/>
		<child link="shoulder_lift_link"/>
		<dynamics damping="1.0" friction="0.0001"/>
		<origin rpy="0.00000 -0.00000 0.00000" xyz="0.00000 0.00000 0.00000"/>
		<axis xyz="0.00000 0.00000 0.00000"/>
	</joint>
	<joint name="upper_arm_roll_joint" type="continuous">
		<parent link="shoulder_lift_link"/>
		<child link="link1_6"/>
		<dynamics damping="1.0" friction="0.0001"/>
		<origin rpy="0.00000 -0.00000 0.00000" xyz="0.00000 0.00000 0.00000"/>
		<axis xyz="1.00000 0.00000 0.00000"/>
	</joint>
	<joint name="jointfix_7_6" type="fixed">
		<parent link="link1_6"/>
		<child link="upper_arm_roll_link"/>
		<dynamics damping="1.0" friction="0.0001"/>
		<origin rpy="0.00000 -0.00000 0.00000" xyz="0.00000 0.00000 0.00000"/>
		<axis xyz="0.00000 0.00000 0.00000"/>
	</joint>
	<joint name="jointfix_6_5" type="fixed">
		<parent link="upper_arm_roll_link"/>
		<child link="upper_arm_link"/>
		<dynamics damping="1.0" friction="0.0001"/>
		<origin rpy="0.00000 -0.00000 0.00000" xyz="0.00000 0.00000 0.00000"/>
		<axis xyz="0.00000 0.00000 0.00000"/>
	</joint>
	<joint name="elbow_flex_joint" type="continuous">
		<parent link="upper_arm_link"/>
		<child link="link1_9"/>
		<dynamics damping="1.0" friction="0.0001"/>
		<origin rpy="0.00000 -0.00000 0.00000" xyz="0.40000 0.00000 0.00000"/>
		<axis xyz="0.00000 1.00000 0.00000"/>
	</joint>
	<joint name="jointfix_5_9" type="fixed">
		<parent link="link1_9"/>
		<child link="elbow_flex_link"/>
		<dynamics damping="1.0" friction="0.0001"/>
		<origin rpy="0.00000 -0.00000 0.00000" xyz="0.00000 0.00000 0.00000"/>
		<axis xyz="0.00000 0.00000 0.00000"/>
	</joint>
	<joint name="forearm_roll_joint" type="continuous">
		<parent link="elbow_flex_link"/>
		<child link="link1_11"/>
		<dynamics damping="1.0" friction="0.0001"/>
		<origin rpy="0.00000 -0.00000 0.00000" xyz="0.00000 0.00000 0.00000"/>
		<axis xyz="1.00000 0.00000 0.00000"/>
	</joint>
	<joint name="jointfix_4_11" type="fixed">
		<parent link="link1_11"/>
		<child link="forearm_roll_link"/>
		<dynamics damping="1.0" friction="0.0001"/>
		<origin rpy="0.00000 -0.00000 0.00000" xyz="0.00000 0.00000 0.00000"/>
		<axis xyz="0.00000 0.00000 0.00000"/>
	</joint>
	<joint name="jointfix_3_10" type="fixed">
		<parent link="forearm_roll_link"/>
		<child link="forearm_link"/>
		<dynamics damping="1.0" friction="0.0001"/>
		<origin rpy="0.00000 -0.00000 0.00000" xyz="0.00000 0.00000 0.00000"/>
		<axis xyz="0.00000 0.00000 0.00000"/>
	</joint>
	<joint name="wrist_flex_joint" type="continuous">
		<parent link="forearm_link"/>
		<child link="link1_14"/>
		<dynamics damping="1.0" friction="0.0001"/>
		<origin rpy="0.00000 -0.00000 0.00000" xyz="0.32100 0.00000 0.00000"/>
		<axis xyz="0.00000 1.00000 0.00000"/>
	</joint>
	<joint name="jointfix_2_14" type="fixed">
		<parent link="link1_14"/>
		<child link="wrist_flex_link"/>
		<dynamics damping="1.0" friction="0.0001"/>
		<origin rpy="0.00000 -0.00000 0.00000" xyz="0.00000 0.00000 0.00000"/>
		<axis xyz="0.00000 0.00000 0.00000"/>
	</joint>
	<joint name="wrist_roll_joint" type="continuous">
		<parent link="wrist_flex_link"/>
		<child link="link1_16"/>
		<dynamics damping="1.0" friction="0.0001"/>
		<origin rpy="0.00000 -0.00000 0.00000" xyz="0.00000 0.00000 0.00000"/>
		<axis xyz="1.00000 0.00000 0.00000"/>
	</joint>
	<joint name="jointfix_1_16" type="fixed">
		<parent link="link1_16"/>
		<child link="wrist_roll_link"/>
		<dynamics damping="1.0" friction="0.0001"/>
		<origin rpy="0.00000 -0.00000 0.00000" xyz="0.00000 0.00000 0.00000"/>
		<axis xyz="0.00000 0.00000 0.00000"/>
	</joint>
	<joint name="jointfix_0_15" type="fixed">
		<parent link="wrist_roll_link"/>
		<child link="fingertip"/>
		<dynamics damping="1.0" friction="0.0001"/>
		<origin rpy="0.00000 -0.00000 0.00000" xyz="0.00000 0.00000 0.00000"/>
		<axis xyz="0.00000 0.00000 0.00000"/>
	</joint>
</robot>
